Failure # 1 (occurred at 2024-12-01_01-37-40)
Traceback (most recent call last):
  File "/home/sarah/miniconda3/envs/hetgppo-env/lib/python3.10/site-packages/ray/tune/execution/ray_trial_executor.py", line 1050, in get_next_executor_event
    future_result = ray.get(ready_future)
  File "/home/sarah/miniconda3/envs/hetgppo-env/lib/python3.10/site-packages/ray/_private/client_mode_hook.py", line 105, in wrapper
    return func(*args, **kwargs)
  File "/home/sarah/miniconda3/envs/hetgppo-env/lib/python3.10/site-packages/ray/_private/worker.py", line 2291, in get
    raise value
ray.exceptions.RayActorError: The actor died because of an error raised in its creation task, [36mray::MultiPPOTrainer.__init__()[39m (pid=459636, ip=160.94.128.252, repr=MultiPPOTrainer)
  File "/home/sarah/miniconda3/envs/hetgppo-env/lib/python3.10/site-packages/ray/rllib/algorithms/algorithm.py", line 414, in __init__
    super().__init__(config=config, logger_creator=logger_creator, **kwargs)
  File "/home/sarah/miniconda3/envs/hetgppo-env/lib/python3.10/site-packages/ray/tune/trainable/trainable.py", line 161, in __init__
    self.setup(copy.deepcopy(self.config))
  File "/home/sarah/miniconda3/envs/hetgppo-env/lib/python3.10/site-packages/ray/rllib/algorithms/algorithm.py", line 524, in setup
    self.workers = WorkerSet(
  File "/home/sarah/miniconda3/envs/hetgppo-env/lib/python3.10/site-packages/ray/rllib/evaluation/worker_set.py", line 157, in __init__
    remote_spaces = ray.get(
ray.exceptions.RaySystemError: System error: RandomNumberGenerator._generator_ctor() takes from 0 to 1 positional arguments but 2 were given
traceback: Traceback (most recent call last):
TypeError: RandomNumberGenerator._generator_ctor() takes from 0 to 1 positional arguments but 2 were given

